{"trial_id": "0248", "hyperparameters": {"space": [{"class_name": "Choice", "config": {"name": "activation", "default": "relu", "conditions": [], "values": ["relu", "tanh"], "ordered": false}}, {"class_name": "Int", "config": {"name": "first_units", "default": null, "conditions": [], "min_value": 16, "max_value": 256, "step": 32, "sampling": "linear"}}, {"class_name": "Int", "config": {"name": "num_layers", "default": null, "conditions": [], "min_value": 1, "max_value": 3, "step": 1, "sampling": "linear"}}, {"class_name": "Int", "config": {"name": "units_0", "default": null, "conditions": [], "min_value": 16, "max_value": 128, "step": 16, "sampling": "linear"}}, {"class_name": "Int", "config": {"name": "units_1", "default": null, "conditions": [], "min_value": 16, "max_value": 128, "step": 16, "sampling": "linear"}}, {"class_name": "Int", "config": {"name": "units_2", "default": null, "conditions": [], "min_value": 16, "max_value": 128, "step": 16, "sampling": "linear"}}], "values": {"activation": "tanh", "first_units": 80, "num_layers": 1, "units_0": 64, "units_1": 112, "units_2": 96, "tuner/epochs": 100, "tuner/initial_epoch": 0, "tuner/bracket": 0, "tuner/round": 0}}, "metrics": {"metrics": {}}, "score": null, "best_step": 0, "status": "FAILED", "message": "Traceback (most recent call last):\n  File \"c:\\Users\\Paul\\anaconda3\\envs\\dev\\lib\\site-packages\\keras_tuner\\src\\engine\\base_tuner.py\", line 274, in _try_run_and_update_trial\n    self._run_and_update_trial(trial, *fit_args, **fit_kwargs)\n  File \"c:\\Users\\Paul\\anaconda3\\envs\\dev\\lib\\site-packages\\keras_tuner\\src\\engine\\base_tuner.py\", line 239, in _run_and_update_trial\n    results = self.run_trial(trial, *fit_args, **fit_kwargs)\n  File \"c:\\Users\\Paul\\anaconda3\\envs\\dev\\lib\\site-packages\\keras_tuner\\src\\tuners\\hyperband.py\", line 427, in run_trial\n    return super().run_trial(trial, *fit_args, **fit_kwargs)\n  File \"c:\\Users\\Paul\\anaconda3\\envs\\dev\\lib\\site-packages\\keras_tuner\\src\\engine\\tuner.py\", line 314, in run_trial\n    obj_value = self._build_and_fit_model(trial, *args, **copied_kwargs)\n  File \"c:\\Users\\Paul\\anaconda3\\envs\\dev\\lib\\site-packages\\keras_tuner\\src\\engine\\tuner.py\", line 233, in _build_and_fit_model\n    results = self.hypermodel.fit(hp, model, *args, **kwargs)\n  File \"c:\\Users\\Paul\\anaconda3\\envs\\dev\\lib\\site-packages\\keras_tuner\\src\\engine\\hypermodel.py\", line 149, in fit\n    return model.fit(*args, **kwargs)\n  File \"c:\\Users\\Paul\\anaconda3\\envs\\dev\\lib\\site-packages\\keras\\src\\utils\\traceback_utils.py\", line 122, in error_handler\n    raise e.with_traceback(filtered_tb) from None\n  File \"c:\\Users\\Paul\\anaconda3\\envs\\dev\\lib\\site-packages\\keras_tuner\\src\\engine\\tuner_utils.py\", line 76, in on_epoch_end\n    self._save_model()\n  File \"c:\\Users\\Paul\\anaconda3\\envs\\dev\\lib\\site-packages\\keras_tuner\\src\\engine\\tuner_utils.py\", line 86, in _save_model\n    self.model.save_weights(write_filepath)\n  File \"c:\\Users\\Paul\\anaconda3\\envs\\dev\\lib\\site-packages\\h5py\\_hl\\files.py\", line 561, in __init__\n    fid = make_fid(name, mode, userblock_size, fapl, fcpl, swmr=swmr)\n  File \"c:\\Users\\Paul\\anaconda3\\envs\\dev\\lib\\site-packages\\h5py\\_hl\\files.py\", line 241, in make_fid\n    fid = h5f.create(name, h5f.ACC_TRUNC, fapl=fapl, fcpl=fcpl)\n  File \"h5py\\\\_objects.pyx\", line 54, in h5py._objects.with_phil.wrapper\n  File \"h5py\\\\_objects.pyx\", line 55, in h5py._objects.with_phil.wrapper\n  File \"h5py\\\\h5f.pyx\", line 122, in h5py.h5f.create\nPermissionError: [Errno 13] Unable to synchronously create file (unable to open file: name = '.\\smart_model_history\\trial_0248\\checkpoint.weights.h5', errno = 13, error message = 'Permission denied', flags = 13, o_flags = 302)\n"}